Workbook

Sheet v1.0-MVP
A1: 任务ID | B1: 任务名称 | C1: TDD阶段 | D1: 所属模块 | E1: 优先级 | F1: 负责角色 | G1: 预估工时 | H1: 开始周 | I1: 结束周 | J1: 前置依赖 | K1: 状态 | L1: 详细任务提示词 | M1: 验收标准 | N1: 备注
A2: MVP-CLI-001 | B2: 克隆VS Code OSS仓库，配置开发环境 | C2: 基础设施 | D2: 客户端基础 | E2: P0 | F2: 全栈 | G2: 2 | H2: 2026-W14 | I2: 2026-W14 | K2: 未开始 | L2: 【目标】搭建织梦笔客户端开发环境，基于VS Code OSS Fork 【技术选型】VS Code OSS (microsoft/vscode), Node.js 20+, Yarn 1.22+ 【具体步骤】 1. 克隆仓库：git clone https://github.com/microsoft/vscode.git --depth 1 2. 安装Node.js 20+：确认node -v >= 20.0.0, npm -v >= 10.0.0 3. 安装Yarn：corepack enable && corepack prepare yarn@1.22.22 --activate 4. 安装依赖：cd vscode && yarn install 5. 编译验证：yarn watch（等待编译完成，确认无错误） 6. 运行验证：yarn electron（启动Electron应用，确认VS Code正常打开） 7. 配置开发环境： - 创建.vscode/settings.json，配置TypeScript strict模式 - 配置ESLint：.eslintrc.json继承VS Code规则 - 配置Prettier：.prettierrc统一代码风格 - 配置launch.json用于F5调试 【配置内容】 { "typescript.tsdk": "node_modules/typescript/lib", "typescript.enablePromptUseWorkspaceTsdk": true, "editor.formatOnSave": true, "editor.defaultFormatter": "esbenp.prettier-vscode" } 【验证命令】yarn watch && yarn electron 【预期结果】VS Code OSS成功编译并启动，无任何错误或警告 | M2: VS Code OSS成功编译启动，F5可调试，ESLint/Prettier配置生效
A3: MVP-CLI-002 | B3: 修改product.json品牌化 | C3: Green实现 | D3: 客户端基础 | E3: P0 | F3: 前端 | G3: 1 | H3: 2026-W14 | I3: 2026-W14 | J3: MVP-CLI-001 | K3: 未开始 | L3: 【目标】将VS Code OSS品牌化为「织梦笔」 【源文件路径】product.json 【实现步骤】 1. 修改product.json中的品牌字段： - nameShort: "织梦笔" - nameLong: "织梦笔 - AI驱动的小说创作工具" - applicationName: "dreamweaver-pen" - dataFolderName: "DreamweaverPen" - reportIssueUrl: "https://github.com/dreamweaver-pen/issues" - licenseUrl: "https://github.com/dreamweaver-pen/license" 2. 替换extensionsGallery端点为自建： - 将"extensionsGallery.serviceUrl"替换为自建扩展市场地址 - 或设为空字符串禁用默认扩展市场 3. 禁用遥测： - 将"enableTelemetry"设为false - 将"aiServices"相关配置清空或禁用 4. 修改quality参数为"oss" 5. 验证yarn watch编译通过 6. 启动应用验证标题栏显示"织梦笔" 【关键代码结构】 - product.json: { nameShort, nameLong, applicationName, dataFolderName, extensionsGallery, enableTelemetry } 【运行命令】yarn watch && yarn electron 【预期结果】应用标题显示"织梦笔"，数据存储在DreamweaverPen目录 | M3: 应用标题显示「织梦笔」，数据目录为DreamweaverPen，遥测已禁用，编译无错误
A4: MVP-CLI-003 | B4: 替换图标和资源文件 | C4: Green实现 | D4: 客户端基础 | E4: P0 | F4: 前端 | G4: 1 | H4: 2026-W14 | I4: 2026-W14 | J4: MVP-CLI-002 | K4: 未开始 | L4: 【目标】替换VS Code OSS默认图标为织梦笔品牌图标 【源文件路径】resources/目录 【实现步骤】 1. 准备织梦笔Logo设计稿（由设计师提供，路径：assets/brand/logo/） 2. 替换各平台图标文件： - macOS: resources/darwin/code.icns → 替换为织梦笔.icns（需要iconutil工具转换） - Windows: resources/win32/code_150x150.png, code_70x70.png, code.ico → 替换为织梦笔图标 - Linux: resources/linux/code.png → 替换为织梦笔.png 3. 替换窗口图标： - resources/code-icon.svg → 替换为织梦笔SVG 4. 生成各尺寸PNG（使用sharp或ImageMagick）： - 16x16, 32x32, 48x48, 64x64, 128x128, 256x256, 512x512 5. 生成macOS .icns文件：iconutil -c icns icon.iconset 6. 生成Windows .ico文件：使用ImageMagick或在线工具 7. 验证各平台图标显示正确 【配置内容】 - macOS图标尺寸：16/32/128/256/512/1024 - Windows图标尺寸：16/32/48/64/128/256 - Linux图标尺寸：64/128/256/512 【验证命令】yarn watch && yarn electron（各平台分别验证） 【预期结果】各平台任务栏、窗口标题、桌面快捷方式均显示织梦笔图标 | M4: macOS/Windows/Linux各平台图标均正确显示织梦笔Logo，无残留VS Code图标
A5: MVP-CLI-004 | B5: 移除不需要的内置功能 | C5: Green实现 | D5: 客户端基础 | E5: P1 | F5: 前端 | G5: 2 | H5: 2026-W14 | I5: 2026-W15 | J5: MVP-CLI-002 | K5: 未开始 | L5: 【目标】移除VS Code中与小说创作无关的内置功能，精简编辑器 【源文件路径】extensions/, src/vs/workbench/contrib/ 【实现步骤】 1. 从extensions/目录移除以下内置扩展： - extensions/debugger-auto-launch/ → 调试器自动启动 - extensions/git/ → Git集成 - extensions/git-base/ → Git基础 - extensions/merge-conflict/ → 合并冲突 - extensions/npm/ → NPM支持 - extensions/debugger-core/ → 调试器核心 - extensions/typescript-language-features/ → 保留但精简 2. 从src/vs/workbench/contrib/移除对应贡献点： - contrib/debug/ → 调试视图 - contrib/scm/ → 源代码管理 - contrib/terminal/ → 终端（可选保留） - contrib/testing/ → 测试面板 - contrib/remote/ → 远程开发 3. 修改默认布局配置： - 隐藏Debug视图 - 隐藏Source Control视图 - 隐藏Extensions视图（或替换为织梦笔扩展市场） 4. 清理package.json中的扩展依赖 5. 验证编译通过：yarn watch 6. 验证移除的面板不再显示 【关键代码结构】 - extensions/ → 删除不需要的扩展目录 - src/vs/workbench/contrib/ → 删除不需要的贡献点 - src/vs/workbench/browser/workbench.contribution.ts → 移除注册 【运行命令】yarn watch（编译验证） 【预期结果】编译通过，移除的面板不再显示，保留核心编辑功能 | M5: 移除的功能面板不再显示，编译无错误，核心编辑功能正常
A6: MVP-CLI-005 | B6: 修改默认Workbench布局 | C6: Green实现 | D6: 客户端基础 | E6: P1 | F6: 前端 | G6: 2 | H6: 2026-W15 | I6: 2026-W15 | J6: MVP-CLI-004 | K6: 未开始 | L6: 【目标】将VS Code默认布局改造为织梦笔小说创作工作台布局 【源文件路径】src/vs/workbench/browser/, src/vs/workbench/contrib/activitybar/ 【实现步骤】 1. 修改Activity Bar默认图标和顺序： - 大纲（📖）→ Story Explorer / 大纲视图 - 分支（🌿）→ Branch Manager / 分支管理 - 知识库（📚）→ Story Bible / 知识库 - AI（🤖）→ AI Assistant / AI助手 - 统计（📊）→ Analytics / 数据统计 - 设置（⚙️）→ Settings / 设置 2. 修改默认侧边栏： - 默认展开"大纲"视图 - 隐藏Explorer文件树（或替换为Story Explorer） 3. 修改底部面板： - 默认面板：AI日志 / 一致性报告 / 版本历史 - 移除Terminal/Problems/Output面板 4. 修改状态栏： - 左侧：显示当前章节名 / 字数统计 - 中间：显示当前AI模型 / Token用量 - 右侧：显示一致性状态 / 保存状态 5. 修改欢迎页： - 替换为织梦笔欢迎页，显示最近作品和快速操作 【关键代码结构】 - src/vs/workbench/browser/parts/activitybar/activitybarActions.ts → 修改Activity Bar项 - src/vs/workbench/browser/parts/statusbar/statusbarPart.ts → 修改状态栏 - src/vs/workbench/contrib/welcome/gettingStarted/ → 修改欢迎页 【运行命令】yarn watch && yarn electron 【预期结果】启动后显示织梦笔定制布局，Activity Bar图标和顺序正确 | M6: Activity Bar显示6个定制图标，侧边栏默认展开大纲，状态栏显示字数/模型/一致性
A7: MVP-CLI-006 | B7: 配置测试框架 | C7: 基础设施 | D7: 客户端基础 | E7: P0 | F7: 全栈 | G7: 1 | H7: 2026-W14 | I7: 2026-W14 | J7: MVP-CLI-001 | K7: 未开始 | L7: 【目标】配置VS Code Extension的单元测试和集成测试框架 【技术选型】Vitest + @vscode/test-electron 【配置文件路径】vitest.config.ts, src/vscode.d.ts 【具体步骤】 1. 安装测试依赖： npm install -D vitest @vitest/coverage-v8 @vscode/test-electron 2. 创建vitest.config.ts： - 配置test.include: ["extensions/**/*.test.ts", "src/**/*.test.ts"] - 配置coverage.provider: "v8" - 配置coverage.reporter: ["text", "html", "lcov"] - 配置test.environment: "node" 3. 创建测试示例文件extensions/dw-ai-assistant/__tests__/sample.test.ts： - describe("Sample Test Suite", () => { it("should pass", () => { expect(1+1).toBe(2); }); }) 4. 配置package.json scripts： - "test": "vitest run" - "test:watch": "vitest" - "test:coverage": "vitest run --coverage" - "test:e2e": "vscode-test" 5. 配置CI集成（为GitHub Actions准备） 6. 运行测试验证框架可用 【配置内容】 // vitest.config.ts import { defineConfig } from 'vitest/config'; export default defineConfig({ test: { include: ['extensions/**/*.test.ts'], coverage: { provider: 'v8', reporter: ['text', 'html'] }, }, }); 【验证命令】npm test 【预期结果】测试框架正确运行，示例测试通过，coverage报告生成 | M7: Vitest测试框架配置完成，示例测试通过，coverage报告可生成
A8: MVP-CLI-007 | B8: 配置GitHub Actions CI | C8: 基础设施 | D8: 客户端基础 | E8: P1 | F8: 全栈 | G8: 1 | H8: 2026-W15 | I8: 2026-W15 | J8: MVP-CLI-006 | K8: 未开始 | L8: 【目标】配置GitHub Actions持续集成流水线 【技术选型】GitHub Actions 【配置文件路径】.github/workflows/ci.yml 【具体步骤】 1. 创建.github/workflows/ci.yml 2. 配置触发条件： - push: branches: [main, develop] - pull_request: branches: [main] 3. 配置lint job： - runs-on: ubuntu-latest - steps: checkout → setup Node.js 20 → yarn install → yarn lint 4. 配置test job： - runs-on: ubuntu-latest - steps: checkout → setup Node.js 20 → yarn install → yarn test - 上传coverage报告为artifact 5. 配置build job： - runs-on: ubuntu-latest - steps: checkout → setup Node.js 20 → yarn install → yarn compile 6. 配置缓存加速： - actions/cache@v4 缓存 node_modules - 缓存 .yarn/cache 7. 配置矩阵测试（可选）：Node.js 20/21 【配置内容】 name: CI on: { push: { branches: [main, develop] }, pull_request: { branches: [main] } } jobs: lint: { runs-on: ubuntu-latest, steps: [checkout, setup-node@20, yarn install, yarn lint] } test: { runs-on: ubuntu-latest, steps: [checkout, setup-node@20, yarn install, yarn test, upload-coverage] } build: { runs-on: ubuntu-latest, steps: [checkout, setup-node@20, yarn install, yarn compile] } 【验证命令】推送代码到GitHub，查看Actions页面 【预期结果】CI流水线lint/test/build三个job全部通过 | M8: GitHub Actions CI配置完成，push/PR触发lint/test/build三个job，全部通过
A9: MVP-SRV-001 | B9: 初始化Go微服务项目 | C9: 基础设施 | D9: 服务端基础 | E9: P0 | F9: 后端 | G9: 2 | H9: 2026-W14 | I9: 2026-W14 | K9: 未开始 | L9: 【目标】搭建织梦笔后端Go微服务项目基础架构 【技术选型】Go 1.22+, Gin, golangci-lint 【配置文件路径】go.mod, Makefile, cmd/, internal/, pkg/ 【具体步骤】 1. 创建项目根目录server/ 2. 初始化Go Module：go mod init github.com/dreamweaver-pen/server 3. 创建monorepo目录结构： server/ ├── cmd/ │ ├── user-service/main.go │ ├── work-service/main.go │ ├── chapter-service/main.go │ ├── branch-service/main.go │ └── bible-service/main.go ├── internal/ │ ├── config/ # 配置管理 │ ├── middleware/ # 中间件 │ ├── models/ # 数据模型 │ └── repository/ # 数据访问层 ├── pkg/ │ ├── response/ # 统一响应 │ ├── logger/ # 日志 │ └── utils/ # 工具函数 ├── go.mod ├── go.sum ├── Makefile └── .golangci.yml 4. 配置Makefile： - make build: 编译所有服务 - make test: 运行测试 - make lint: 代码检查 - make run SERVICE=user: 运行指定服务 5. 配置golangci-lint：.golangci.yml 6. 创建健康检查端点：GET /health → {"status": "ok", "service": "user-service"} 7. 验证编译和运行 【配置内容】 # Makefile .PHONY: build test lint run build: go build -o bin/ ./cmd/... test: go test -v -cover ./... lint: golangci-lint run run: go run ./cmd/$(SERVICE) 【验证命令】make build && make test && make run SERVICE=user-service 【预期结果】所有服务编译成功，健康检查端点返回200 | M9: Go项目结构创建完成，所有服务编译通过，健康检查返回200
A10: MVP-SRV-002 | B10: 初始化Python AI服务项目 | C10: 基础设施 | D10: 服务端基础 | E10: P0 | F10: AI工程师 | G10: 2 | H10: 2026-W14 | I10: 2026-W14 | K10: 未开始 | L10: 【目标】搭建织梦笔AI引擎Python服务基础架构 【技术选型】Python 3.12+, FastAPI, uvicorn, pytest, ruff 【配置文件路径】ai-service/pyproject.toml, ai-service/app/ 【具体步骤】 1. 创建ai-service/目录 2. 初始化项目：创建pyproject.toml 3. 创建目录结构： ai-service/ ├── app/ │ ├── __init__.py │ ├── main.py # FastAPI应用入口 │ ├── api/ │ │ ├── __init__.py │ │ ├── routes/ │ │ │ ├── ai.py # AI生成端点 │ │ │ ├── rag.py # RAG端点 │ │ │ └── consistency.py # 一致性检查端点 │ │ └── deps.py # 依赖注入 │ ├── services/ │ │ ├── __init__.py │ │ ├── ai_service.py # AI服务核心 │ │ ├── rag_service.py # RAG服务 │ │ ├── consistency/ # 一致性检查 │ │ └── entity_extractor.py # 实体提取 │ ├── adapters/ │ │ ├── __init__.py │ │ ├── base.py # 适配器基类 │ │ ├── claude.py # Claude适配器 │ │ ├── deepseek.py # DeepSeek适配器 │ │ └── qwen.py # 通义千问适配器 │ ├── models/ │ │ ├── __init__.py │ │ └── schemas.py # Pydantic模型 │ └── config.py # 配置管理 ├── tests/ │ ├── conftest.py │ ├── test_ai.py │ └── test_rag.py ├── pyproject.toml └── ruff.toml 4. 配置pyproject.toml： - 依赖：fastapi, uvicorn, anthropic, openai, pymilvus, redis, elasticsearch - 开发依赖：pytest, pytest-asyncio, httpx, ruff, mypy 5. 配置ruff.toml：lint规则 6. 创建健康检查端点：GET /health 7. 验证uvicorn运行 【配置内容】 # pyproject.toml (关键部分) [project] name = "dreamweaver-ai" requires-python = ">=3.12" dependencies = ["fastapi>=0.110", "uvicorn>=0.27", "anthropic>=0.18", "openai>=1.12"] [tool.pytest.ini_options] asyncio_mode = "auto" 【验证命令】cd ai-service && uvicorn app.main:app --reload 【预期结果】FastAPI服务启动，/health返回200，Swagger文档可访问 | M10: Python AI服务结构创建完成，FastAPI启动成功，/health返回200，Swagger可访问
A11: MVP-SRV-003 | B11: 搭建PostgreSQL + Schema迁移 | C11: 基础设施 | D11: 服务端基础 | E11: P0 | F11: 后端 | G11: 1 | H11: 2026-W14 | I11: 2026-W14 | K11: 未开始 | L11: 【目标】搭建PostgreSQL数据库并创建全部数据表 【技术选型】PostgreSQL 16, golang-migrate 【配置文件路径】docker-compose.yml, migrations/001_init_schema.sql 【具体步骤】 1. 在docker-compose.yml中添加PostgreSQL 16服务： - image: postgres:16-alpine - ports: 5432:5432 - environment: POSTGRES_DB=dreamweaver, POSTGRES_USER=dw, POSTGRES_PASSWORD=dw_secret - volumes: pgdata:/var/lib/postgresql/data 2. 创建migrations/001_init_schema.sql，包含以下12张表： a. users: id, email, password_hash, nickname, avatar_url, created_at, updated_at b. user_settings: id, user_id, default_model, writing_style, auto_save_interval c. user_model_configs: id, user_id, model_id, api_key_encrypted, is_active d. works: id, user_id, title, genre, description, status, word_count, created_at, updated_at e. chapters: id, work_id, volume_number, chapter_number, title, content, status, word_count, branch_id, created_at, updated_at f. chapter_versions: id, chapter_id, version_number, content, word_count, commit_message, created_at g. branches: id, work_id, parent_id, name, branch_type, fork_point_chapter_id, fork_point_version_id, is_active, created_at h. story_bible_entries: id, work_id, entry_type, name, description, attributes_json, tags, created_at, updated_at i. story_bible_relations: id, work_id, source_entry_id, target_entry_id, relation_type, description j. ai_generation_logs: id, user_id, work_id, chapter_id, model_id, prompt_tokens, completion_tokens, latency_ms, created_at k. consistency_reports: id, work_id, chapter_id, warnings_json, score, created_at l. foreshadowing: id, work_id, chapter_id, description, status, resolved_chapter_id, created_at, updated_at 3. 配置golang-migrate工具 4. 执行迁移验证 【配置内容】 # docker-compose.yml (PostgreSQL部分) postgres: image: postgres:16-alpine ports: ["5432:5432"] environment: POSTGRES_DB: dreamweaver POSTGRES_USER: dw POSTGRES_PASSWORD: dw_secret volumes: [pgdata:/var/lib/postgresql/data] 【验证命令】docker-compose up postgres && migrate -path migrations -database "postgres://dw:dw_secret@localhost:5432/dreamweaver?sslmode=disable" up 【预期结果】PostgreSQL启动成功，12张表创建成功，外键关系正确 | M11: PostgreSQL启动成功，12张表全部创建，外键关系正确，迁移可重复执行
A12: MVP-SRV-004 | B12: 搭建Redis缓存 | C12: 基础设施 | D12: 服务端基础 | E12: P1 | F12: 后端 | G12: 1 | H12: 2026-W14 | I12: 2026-W14 | K12: 未开始 | L12: 【目标】搭建Redis缓存服务，用于会话管理、Token缓存、限流计数 【技术选型】Redis 7, go-redis/v9 (Go), redis-py (Python) 【配置文件路径】docker-compose.yml, pkg/cache/redis.go, app/config.py 【具体步骤】 1. docker-compose.yml添加Redis 7服务： - image: redis:7-alpine - ports: 6379:6379 - command: redis-server --maxmemory 256mb --maxmemory-policy allkeys-lru - volumes: redisdata:/data 2. Go集成go-redis/v9： - pkg/cache/redis.go → NewRedisClient(addr, password) → Get/Set/Del/Expire - 配置连接池：PoolSize=10, MinIdleConns=2 3. Python集成redis-py： - app/config.py → REDIS_URL配置 - app/services/cache.py → get_redis_client() → get/set/delete 4. 编写缓存工具函数： - cache_get(key) → Optional[bytes] - cache_set(key, value, ttl) → bool - cache_delete(key) → bool - cache_incr(key) → int（用于限流计数） 5. 验证读写正常 【配置内容】 # Go连接配置 redis.NewClient(&redis.Options{ Addr: "localhost:6379", Password: "", PoolSize: 10, MinIdleConns: 2, }) 【验证命令】docker-compose up redis && redis-cli ping → PONG 【预期结果】Redis启动成功，Go和Python客户端均可正常读写 | M12: Redis启动成功，Go/Python客户端读写正常，连接池配置生效
A13: MVP-SRV-005 | B13: 搭建RabbitMQ消息队列 | C13: 基础设施 | D13: 服务端基础 | E13: P1 | F13: 后端 | G13: 1 | H13: 2026-W15 | I13: 2026-W15 | K13: 未开始 | L13: 【目标】搭建RabbitMQ消息队列，用于异步任务（AI生成、实体提取、一致性检查） 【技术选型】RabbitMQ 3.13, amqp091-go (Go), pika (Python) 【配置文件路径】docker-compose.yml, pkg/mq/rabbitmq.go, app/services/mq.py 【具体步骤】 1. docker-compose.yml添加RabbitMQ 3.13服务： - image: rabbitmq:3.13-management-alpine - ports: 5672:5672 (AMQP), 15672:15672 (管理界面) - environment: RABBITMQ_DEFAULT_USER=dw, RABBITMQ_DEFAULT_PASS=dw_secret 2. 定义Exchange和Queue： - Exchange: dw.direct (direct类型) - Queue: dw.chapter.saved → 章节保存后触发实体提取+一致性检查 - Queue: dw.ai.generation.request → AI生成请求 - Queue: dw.ai.generation.result → AI生成结果 - Queue: dw.consistency.check.request → 一致性检查请求 - Queue: dw.consistency.check.result → 一致性检查结果 3. Go集成amqp091-go： - pkg/mq/rabbitmq.go → NewRabbitMQClient() → Publish/Consume - 定义消息格式：JSON { task_type, payload, created_at } 4. Python集成pika： - app/services/mq.py → get_mq_connection() → publish/consume 5. 验证消息发布和消费 【配置内容】 # Queue绑定 dw.chapter.saved → routing_key: chapter.saved dw.ai.generation.request → routing_key: ai.generation.request dw.consistency.check.request → routing_key: consistency.check.request 【验证命令】docker-compose up rabbitmq → 访问 http://localhost:15672 管理界面 【预期结果】RabbitMQ启动成功，Exchange和Queue创建成功，消息发布消费正常 | M13: RabbitMQ启动成功，管理界面可访问，消息发布消费正常
A14: MVP-SRV-006 | B14: 搭建Milvus向量数据库 | C14: 基础设施 | D14: 服务端基础 | E14: P0 | F14: AI工程师 | G14: 1 | H14: 2026-W15 | I14: 2026-W15 | K14: 未开始 | L14: 【目标】搭建Milvus向量数据库，用于RAG语义检索 【技术选型】Milvus 2.4, pymilvus (Python) 【配置文件路径】docker-compose.yml, app/services/vector_store.py 【具体步骤】 1. docker-compose.yml添加Milvus 2.4服务： - image: milvusdb/milvus:v2.4.0 - ports: 19530:19530 (gRPC), 9091:9091 (metrics) - environment: ETCD_ENDPOINTS=etcd:2379 - 依赖：etcd + minio 2. Python集成pymilvus： - app/services/vector_store.py → VectorStore类 3. 创建Collection（dw_chapter_segments）： - id: INT64 (PK) - work_id: INT64 - chapter_id: INT64 - segment_index: INT64 - content: VARCHAR(8192) - embedding: FLOAT_VECTOR(1536) # text-embedding-3-large维度 - Index: IVF_FLAT, nlist=1024 4. 创建Collection（dw_bible_entities）： - id: INT64 (PK) - work_id: INT64 - entry_id: INT64 - entry_type: VARCHAR(32) - name: VARCHAR(256) - description: VARCHAR(4096) - embedding: FLOAT_VECTOR(1536) - Index: IVF_FLAT, nlist=512 5. 编写向量CRUD工具函数： - insert_vectors(collection, data) → ids - search_vectors(collection, vector, top_k, filter) → results - delete_vectors(collection, ids) 6. 验证插入和检索 【配置内容】 # Collection Schema dw_chapter_segments: { id, work_id, chapter_id, segment_index, content, embedding(1536) } dw_bible_entities: { id, work_id, entry_id, entry_type, name, description, embedding(1536) } 【验证命令】python -c "from pymilvus import connections; connections.connect(); print('OK')" 【预期结果】Milvus启动成功，两个Collection创建成功，向量插入和检索正常 | M14: Milvus启动成功，两个Collection创建，向量插入和语义检索正常
A15: MVP-SRV-007 | B15: 搭建Elasticsearch | C15: 基础设施 | D15: 服务端基础 | E15: P1 | F15: 后端 | G15: 1 | H15: 2026-W15 | I15: 2026-W15 | K15: 未开始 | L15: 【目标】搭建Elasticsearch全文搜索引擎，用于知识库和章节内容搜索 【技术选型】Elasticsearch 8.x, olivere/elastic (Go), elasticsearch-py (Python) 【配置文件路径】docker-compose.yml, pkg/search/es.go, app/services/search.py 【具体步骤】 1. docker-compose.yml添加ES 8.x服务： - image: elasticsearch:8.12.0 - ports: 9200:9200 (HTTP), 9300:9300 (Transport) - environment: discovery.type=single-node, xpack.security.enabled=false, ES_JAVA_OPTS=-Xms512m -Xmx512m - volumes: esdata:/usr/share/elasticsearch/data 2. Go集成olivere/elastic： - pkg/search/es.go → NewESClient(url) → Index/Search/Delete 3. Python集成elasticsearch-py： - app/services/search.py → get_es_client() → index/search 4. 创建索引模板： - dw_chapters: { work_id, chapter_id, title, content, chapter_number, updated_at } → content字段使用ik_max_word分词器 - dw_bible: { work_id, entry_id, entry_type, name, description, tags } → name和description使用ik_max_word分词器 5. 验证索引和搜索 【配置内容】 # dw_chapters索引映射 { "mappings": { "properties": { "work_id": { "type": "long" }, "content": { "type": "text", "analyzer": "ik_max_word" } } } } 【验证命令】curl http://localhost:9200/_cluster/health?pretty 【预期结果】ES启动成功，索引创建成功，中文分词和搜索正常 | M15: Elasticsearch启动成功，索引创建成功，中文分词和全文搜索正常
A16: MVP-SRV-008 | B16: 搭建Kong API网关 | C16: 基础设施 | D16: 服务端基础 | E16: P1 | F16: 后端 | G16: 2 | H16: 2026-W15 | I16: 2026-W15 | J16: MVP-SRV-001 | K16: 未开始 | L16: 【目标】搭建Kong API网关，统一管理所有微服务API路由 【技术选型】Kong 3.6, PostgreSQL (Kong数据存储) 【配置文件路径】docker-compose.yml, kong/ 【具体步骤】 1. docker-compose.yml添加Kong服务： - image: kong:3.6 - ports: 8000:8000 (Proxy), 8443:8443 (Proxy SSL), 8001:8001 (Admin API) - environment: KONG_DATABASE=postgres, KONG_PG_HOST=kong-db - 依赖：kong-db (PostgreSQL) 2. 配置Service和Route： - Service: user-service → upstream: http://user-service:8001 Route: /api/v1/auth/*, /api/v1/users/* - Service: work-service → upstream: http://work-service:8002 Route: /api/v1/works/* - Service: chapter-service → upstream: http://chapter-service:8003 Route: /api/v1/chapters/* - Service: branch-service → upstream: http://branch-service:8004 Route: /api/v1/branches/* - Service: bible-service → upstream: http://bible-service:8005 Route: /api/v1/bible/* - Service: ai-service → upstream: http://ai-service:8006 Route: /api/v1/ai/* 3. 配置JWT认证Plugin： - 全局JWT Plugin - 配置issuer和secret 4. 配置限流Plugin： - rate-limiting: 100 req/min per consumer 5. 配置CORS： - 允许Origin: vscode-webview, localhost:3000 - 允许Methods: GET, POST, PUT, DELETE 6. 验证API路由和认证 【配置内容】 # Kong配置（通过Admin API或declarative config） services: - name: user-service, url: http://user-service:8001 - name: ai-service, url: http://ai-service:8006 routes: - name: auth-route, service: user-service, paths: ["/api/v1/auth"] - name: ai-route, service: ai-service, paths: ["/api/v1/ai"] plugins: - name: jwt, config: { claims_to_verify: ["exp"] } - name: rate-limiting, config: { minute: 100, policy: "local" } - name: cors, config: { origins: ["*"], methods: ["GET","POST","PUT","DELETE"] } 【验证命令】curl -I http://localhost:8000/api/v1/auth/health 【预期结果】Kong启动成功，API路由正确转发，JWT认证生效，限流生效 | M16: Kong启动成功，所有微服务API路由正确，JWT认证和限流生效
A17: MVP-SRV-009 | B17: 配置Docker Compose开发环境 | C17: 基础设施 | D17: 服务端基础 | E17: P0 | F17: 全栈 | G17: 1 | H17: 2026-W15 | I17: 2026-W15 | J17: MVP-SRV-003,MVP-SRV-004,MVP-SRV-005 | K17: 未开始 | L17: 【目标】整合所有服务到Docker Compose开发环境，实现一键启动 【技术选型】Docker Compose v2 【配置文件路径】docker-compose.dev.yml, .env.example, Makefile 【具体步骤】 1. 创建docker-compose.dev.yml，整合所有服务： - postgres (PostgreSQL 16) - redis (Redis 7) - rabbitmq (RabbitMQ 3.13 + management) - milvus (Milvus 2.4 + etcd + minio) - elasticsearch (Elasticsearch 8.x) - kong (Kong 3.6 + kong-db) - user-service (Go, build from Dockerfile) - ai-service (Python, build from Dockerfile) 2. 配置网络： - dw-network: 所有服务共用 3. 配置卷： - pgdata, redisdata, esdata, milvus-data 4. 配置环境变量.env.example： - DATABASE_URL=postgres://dw:dw_secret@localhost:5432/dreamweaver - REDIS_URL=redis://localhost:6379 - RABBITMQ_URL=amqp://dw:dw_secret@localhost:5672 - MILVUS_HOST=localhost, MILVUS_PORT=19530 - ELASTICSEARCH_URL=http://localhost:9200 - ANTHROPIC_API_KEY=sk-ant-xxx - DEEPSEEK_API_KEY=sk-xxx - JWT_SECRET=your-jwt-secret-change-in-production 5. 配置健康检查： - 每个服务配置healthcheck 6. 编写Makefile快捷命令： - make dev: docker-compose -f docker-compose.dev.yml up - make test: 运行所有测试 - make migrate: 执行数据库迁移 - make down: 停止所有服务 - make logs: 查看日志 7. 验证一键启动 【配置内容】 # Makefile dev: docker-compose -f docker-compose.dev.yml up --build test: cd server && go test ./... && cd ../ai-service && pytest migrate: migrate -path migrations -database "$(DATABASE_URL)" up down: docker-compose -f docker-compose.dev.yml down logs: docker-compose -f docker-compose.dev.yml logs -f 【验证命令】cp .env.example .env && make dev 【预期结果】docker-compose up一键启动所有服务，所有健康检查通过 | M17: Docker Compose一键启动所有服务，健康检查全部通过，Makefile命令可用
A18: MVP-SRV-010 | B18: 配置Kubernetes部署清单 | C18: 基础设施 | D18: 服务端基础 | E18: P2 | F18: 后端 | G18: 2 | H18: 2026-W15 | I18: 2026-W15 | J18: MVP-SRV-009 | K18: 未开始 | L18: 【目标】创建Kubernetes部署清单，用于生产环境部署 【技术选型】Kubernetes 1.29+, Helm (可选) 【配置文件路径】k8s/ 【具体步骤】 1. 创建k8s/namespace.yaml： - name: dreamweaver 2. 创建各服务的Deployment+Service+HPA YAML： - k8s/user-service/deployment.yaml, service.yaml, hpa.yaml - k8s/ai-service/deployment.yaml, service.yaml, hpa.yaml - k8s/work-service/deployment.yaml, service.yaml, hpa.yaml - k8s/chapter-service/deployment.yaml, service.yaml, hpa.yaml - k8s/branch-service/deployment.yaml, service.yaml, hpa.yaml - k8s/bible-service/deployment.yaml, service.yaml, hpa.yaml 3. 每个Deployment配置： - replicas: 2 - resources: requests { cpu: 100m, memory: 128Mi }, limits { cpu: 500m, memory: 512Mi } - livenessProbe: /health - readinessProbe: /health - envFrom: ConfigMap + Secret 4. 创建ConfigMap和Secret： - k8s/configmap.yaml: 非敏感配置 - k8s/secret.yaml: 敏感配置（API Keys, JWT Secret） 5. 创建Ingress： - k8s/ingress.yaml: 域名路由配置 - TLS配置 6. 编写Helm Chart（可选）： - k8s/helm/Chart.yaml, values.yaml, templates/ 7. 验证kubectl apply成功 【配置内容】 # Deployment示例 apiVersion: apps/v1 kind: Deployment metadata: { name: user-service, namespace: dreamweaver } spec: replicas: 2 template: spec: containers: - name: user-service image: dreamweaver/user-service:latest ports: [{ containerPort: 8001 }] resources: { requests: { cpu: 100m, memory: 128Mi }, limits: { cpu: 500m, memory: 512Mi } } livenessProbe: { httpGet: { path: /health, port: 8001 } } 【验证命令】kubectl apply -f k8s/ && kubectl get pods -n dreamweaver 【预期结果】所有Pod正常运行，Service可访问，HPA自动扩缩容 | M18: K8s清单创建完成，kubectl apply成功，所有Pod正常运行
A19: MVP-AUTH-001 | B19: 用户注册API - 测试 | C19: Red测试 | D19: 用户系统 | E19: P0 | F19: 后端 | G19: 1 | H19: 2026-W14 | I19: 2026-W14 | J19: MVP-SRV-003 | K19: 未开始 | L19: 【目标】编写用户注册API的完整单元测试和集成测试 【测试框架】pytest + httpx 【测试文件路径】ai-service/tests/auth/test_register.py 【测试用例清单】 1. test_register_success：正常注册（邮箱+密码+昵称）→ 期望返回201 + JWT Token + 用户信息 - 请求：POST /api/v1/auth/register {"email":"test@example.com","password":"Test@12345","nickname":"测试用户"} - 断言：status_code==201, response["access_token"]存在, response["user"]["email"]=="test@example.com" 2. test_register_duplicate_email：重复邮箱注册 → 期望返回409 Conflict - 先注册一个用户，再用相同邮箱注册 - 断言：status_code==409, response["detail"]=="邮箱已注册" 3. test_register_weak_password：弱密码注册 → 期望返回422 - 密码不足8位 → 断言：status_code==422 - 密码无大写字母 → 断言：status_code==422 - 密码无特殊字符 → 断言：status_code==422 4. test_register_invalid_email：无效邮箱格式 → 期望返回422 - 请求：{"email":"invalid","password":"Test@12345","nickname":"测试"} - 断言：status_code==422 5. test_register_empty_fields：空字段 → 期望返回422 - 缺少email/password/nickname各测试一次 6. test_register_password_hashed：验证密码已哈希存储 - 注册后查询数据库，确认password_hash不是明文 - 断言：password_hash != "Test@12345", password_hash.startswith("$2b$") 7. test_register_token_structure：验证JWT Token结构 - 解码access_token，验证payload包含user_id, exp, iat - 验证access_token过期时间为24h - 验证refresh_token过期时间为7d 【Mock依赖】 - Mock PostgreSQL数据库（使用pytest fixture创建测试数据库） - Mock邮件发送服务（注册确认邮件） 【断言要点】 - 状态码正确（201/409/422） - JWT Token格式正确（三段式base64） - 密码使用bcrypt哈希（$2b$开头） - 用户信息返回正确（email, nickname, id） - 错误信息不泄露敏感信息 【运行命令】cd ai-service && pytest tests/auth/test_register.py -v 【预期结果】所有7个测试用例通过 | M19: 7个测试用例全部通过，覆盖正常注册、重复邮箱、弱密码、无效邮箱、空字段、密码哈希、Token结构
A20: MVP-AUTH-002 | B20: 用户注册API - 实现 | C20: Green实现 | D20: 用户系统 | E20: P0 | F20: 后端 | G20: 2 | H20: 2026-W14 | I20: 2026-W14 | J20: MVP-AUTH-001 | K20: 未开始 | L20: 【目标】实现用户注册API，使MVP-AUTH-001中所有测试通过 【源文件路径】ai-service/app/api/routes/auth.py, ai-service/app/services/auth_service.py 【API端点】POST /api/v1/auth/register 【数据模型】 - 请求体：RegisterRequest { email: EmailStr, password: str, nickname: str } - 响应体：RegisterResponse { access_token: str, refresh_token: str, token_type: str, user: UserInfo } - 数据库表：users { id, email, password_hash, nickname, avatar_url, created_at, updated_at } 【实现步骤】 1. 创建Pydantic模型（app/models/schemas.py）： - RegisterRequest: email(EmailStr), password(min_length=8, regex), nickname(min_length=1, max_length=32) - UserInfo: id, email, nickname, avatar_url, created_at - TokenResponse: access_token, refresh_token, token_type="bearer" 2. 实现密码验证逻辑： - 至少8位字符 - 包含大写字母、小写字母、数字、特殊字符 - 正则：^(?=.*[a-z])(?=.*[A-Z])(?=.*\d)(?=.*[@$!%*?&])[A-Za-z\d@$!%*?&]{8,}$ 3. 实现auth_service.py： - async register_user(db, email, password, nickname) → User - bcrypt.hashpw(password, bcrypt.gensalt(rounds=12)) - INSERT INTO users (email, password_hash, nickname) VALUES (...) - 检查邮箱唯一性（UNIQUE约束 + 显式查询） 4. 实现JWT生成： - generate_access_token(user_id) → JWT(exp=24h) - generate_refresh_token(user_id) → JWT(exp=7d) - 使用PyJWT库，HS256算法 5. 实现路由（app/api/routes/auth.py）： - @router.post("/register", status_code=201, response_model=TokenResponse) - 错误处理：409邮箱已存在, 422参数验证失败 6. 注册路由到FastAPI app 【关键代码结构】 - 入口函数签名：async def register(request: RegisterRequest, db: AsyncSession) → TokenResponse - 核心逻辑：验证参数 → 检查邮箱唯一 → 哈希密码 → 插入用户 → 生成Token → 返回 - 错误处理：HTTPException(409, "邮箱已注册") / HTTPException(422, detail=validation_errors) 【依赖注入】 - 数据库Session（通过FastAPI Depends） - JWT_SECRET配置（环境变量） 【运行命令】pytest tests/auth/test_register.py -v（验证所有测试通过） 【预期结果】所有7个测试用例通过 | M20: 用户注册API实现完成，所有测试通过，密码bcrypt哈希，JWT Token正确生成
A21: MVP-AUTH-003 | B21: 用户注册API - 验收 | C21: Acceptance验收 | D21: 用户系统 | E21: P0 | F21: 后端 | G21: 1 | H21: 2026-W14 | I21: 2026-W14 | J21: MVP-AUTH-002 | K21: 未开始 | L21: 【目标】用户注册API的端到端验收测试 【测试范围】从HTTP请求到数据库写入的完整链路 【测试场景】 1. 正常流程：用户提交注册 → 系统返回Token → 验证Token可用 → 验证数据库有记录 - POST /api/v1/auth/register → 201 → 解码Token → 查询数据库确认用户存在 2. 异常流程：重复邮箱注册 → 系统返回409 → 验证错误信息不泄露已有用户信息 - 注册两次相同邮箱 → 第二次返回409 → 错误信息为"邮箱已注册" 3. 边界流程：密码刚好8位+满足所有规则 → 注册成功 - 密码"Abc123!@" → 201成功 4. 安全流程：SQL注入测试 → 注册邮箱包含SQL注入字符串 → 系统正确处理 - email: "test'; DROP TABLE users;--@example.com" → 422（邮箱格式无效） 5. 性能流程：注册响应时间 ≤ 200ms - 使用time测量API响应时间 【测试工具】httpx.AsyncClient + pytest-asyncio 【验收检查项】 □ 功能正确性：正常注册返回201+Token+用户信息 □ 错误处理：重复邮箱409，弱密码422，无效邮箱422 □ 安全：密码bcrypt哈希存储，JWT签名正确，错误信息不泄露敏感数据 □ 性能：注册API响应时间 ≤ 200ms（P95） □ 数据完整性：数据库记录与返回信息一致 【代码审查要点】 □ 代码风格符合ruff规则（ruff check通过） □ 无硬编码的密钥/URL（JWT_SECRET从环境变量读取） □ 有适当的日志记录（注册成功/失败日志） □ 有适当的错误处理（所有异常路径有处理） □ SQL使用参数化查询（防SQL注入） □ 密码哈希使用bcrypt rounds=12 【运行命令】pytest tests/auth/test_register.py -v --tb=short 【预期结果】所有验收项通过，代码审查无问题 | M21: 端到端验收通过，安全测试通过，性能≤200ms，代码审查无问题
A22: MVP-AUTH-004 | B22: 用户登录API - 测试 | C22: Red测试 | D22: 用户系统 | E22: P0 | F22: 后端 | G22: 1 | H22: 2026-W14 | I22: 2026-W14 | J22: MVP-AUTH-003 | K22: 未开始 | L22: 【目标】编写用户登录API的完整测试 【测试框架】pytest + httpx 【测试文件路径】ai-service/tests/auth/test_login.py 【测试用例清单】 1. test_login_success：正常登录 → 期望返回200 + JWT Token - 先注册用户，再POST /api/v1/auth/login {"email":"test@example.com","password":"Test@12345"} - 断言：status_code==200, access_token存在, refresh_token存在 2. test_login_wrong_password：密码错误 → 期望返回401 - 断言：status_code==401, detail=="邮箱或密码错误" 3. test_login_user_not_found：用户不存在 → 期望返回401 - 断言：status_code==401（不区分用户不存在和密码错误，防止枚举攻击） 4. test_login_empty_fields：空字段 → 期望返回422 5. test_login_rate_limit：多次失败后锁定 → 期望返回429 - 连续5次密码错误 → 第6次返回429 "账户已锁定，请15分钟后重试" 6. test_refresh_token：使用refresh_token刷新 → 期望返回新的access_token - POST /api/v1/auth/refresh {"refresh_token": "xxx"} - 断言：status_code==200, 新access_token与旧的不同 7. test_refresh_token_expired：过期refresh_token → 期望返回401 【Mock依赖】Mock PostgreSQL, Mock Redis（失败计数） 【断言要点】状态码正确，Token结构正确，失败计数正确，锁定机制生效 【运行命令】pytest tests/auth/test_login.py -v | M22: 7个测试用例通过，覆盖正常登录、密码错误、用户不存在、锁定、Token刷新
A23: MVP-AUTH-005 | B23: 用户登录API - 实现 | C23: Green实现 | D23: 用户系统 | E23: P0 | F23: 后端 | G23: 2 | H23: 2026-W14 | I23: 2026-W14 | J23: MVP-AUTH-004 | K23: 未开始 | L23: 【目标】实现用户登录API和Token刷新API 【源文件路径】ai-service/app/api/routes/auth.py, ai-service/app/services/auth_service.py 【API端点】POST /api/v1/auth/login, POST /api/v1/auth/refresh 【数据模型】 - LoginRequest: { email: EmailStr, password: str } - RefreshRequest: { refresh_token: str } 【实现步骤】 1. 实现login逻辑： - 查询用户（SELECT * FROM users WHERE email = ?） - bcrypt.checkpw(password, stored_hash) - Redis记录失败次数（key: login_fail:{email}, TTL: 15min） - 失败≥5次 → 返回429 - 成功 → 清除失败计数 → 生成JWT → 返回Token 2. 实现refresh逻辑： - 解码refresh_token → 验证签名和过期时间 - 查询用户是否存在 - 生成新access_token → 返回 3. 错误处理： - 401: 邮箱或密码错误（统一错误信息，不区分用户不存在和密码错误） - 429: 账户锁定 - 401: refresh_token无效或过期 【关键代码结构】 async def login(request: LoginRequest, db: AsyncSession, redis: Redis) → TokenResponse async def refresh_token(request: RefreshRequest, db: AsyncSession) → TokenResponse 【运行命令】pytest tests/auth/test_login.py -v | M23: 登录API实现完成，失败锁定、Token刷新功能正常，所有测试通过
A24: MVP-AUTH-006 | B24: 用户登录API - 验收 | C24: Acceptance验收 | D24: 用户系统 | E24: P0 | F24: 后端 | G24: 1 | H24: 2026-W14 | I24: 2026-W14 | J24: MVP-AUTH-005 | K24: 未开始 | L24: 【目标】用户登录API端到端验收 【测试范围】完整登录→Token刷新→安全测试链路 【测试场景】 1. 正常流程：注册→登录→使用Token访问受保护API→刷新Token→使用新Token访问 2. 异常流程：密码错误5次→锁定→等待15分钟→解锁 3. 安全测试：SQL注入、XSS（邮箱字段）、Token伪造 4. 性能测试：登录响应≤200ms 【测试工具】httpx.AsyncClient + pytest-asyncio 【验收检查项】 □ 功能正确性：登录返回Token，Token可用于认证 □ 安全：密码错误不区分用户不存在，失败锁定生效，Token签名正确 □ 性能：登录≤200ms，Token刷新≤100ms □ 代码审查：无硬编码密钥，参数化查询，适当日志 【运行命令】pytest tests/auth/test_login.py -v | M24: 登录验收通过，安全测试通过，性能达标，代码审查无问题
A25: MVP-AUTH-007 | B25: OAuth第三方登录 - 测试 | C25: Red测试 | D25: 用户系统 | E25: P1 | F25: 后端 | G25: 1 | H25: 2026-W14 | I25: 2026-W14 | J25: MVP-AUTH-003 | K25: 未开始 | L25: 【目标】编写OAuth第三方登录测试 【测试框架】pytest + httpx + respx（Mock HTTP） 【测试文件路径】ai-service/tests/auth/test_oauth.py 【测试用例清单】 1. test_wechat_oauth_callback：微信OAuth回调处理 - Mock微信API返回access_token + userinfo - 断言：返回JWT Token，新用户创建成功 2. test_google_oauth_callback：Google OAuth回调 - Mock Google API返回userinfo - 断言：返回JWT Token 3. test_oauth_new_user_auto_create：新用户自动创建 - 首次OAuth登录 → 自动创建用户记录 - 断言：数据库有新用户，nickname从OAuth provider获取 4. test_oauth_existing_user_login：已有用户直接登录 - 已绑定的OAuth用户再次登录 → 直接返回Token - 断言：不创建重复用户 5. test_oauth_invalid_code：无效授权码 → 期望返回401 6. test_oauth_provider_not_supported：不支持的Provider → 期望返回400 【Mock依赖】Mock微信API、GoogleAPI（使用respx库） 【断言要点】Token返回正确，用户创建/查找正确，错误处理正确 【运行命令】pytest tests/auth/test_oauth.py -v | M25: 6个OAuth测试用例通过，覆盖微信/Google登录、新用户创建、已有用户登录
A26: MVP-AUTH-008 | B26: OAuth第三方登录 - 实现 | C26: Green实现 | D26: 用户系统 | E26: P1 | F26: 后端 | G26: 2 | H26: 2026-W14 | I26: 2026-W14 | J26: MVP-AUTH-007 | K26: 未开始 | L26: 【目标】实现微信和Google OAuth第三方登录 【源文件路径】ai-service/app/api/routes/auth.py, ai-service/app/services/oauth_service.py 【API端点】 - GET /api/v1/auth/oauth/{provider} → 重定向到OAuth Provider - GET /api/v1/auth/oauth/{provider}/callback → 处理回调 【实现步骤】 1. 创建OAuth配置： - WECHAT_APP_ID, WECHAT_APP_SECRET - GOOGLE_CLIENT_ID, GOOGLE_CLIENT_SECRET 2. 实现OAuthService： - get_authorization_url(provider) → str - handle_callback(provider, code) → TokenResponse 3. 微信OAuth流程： - 重定向到 https://open.weixin.qq.com/connect/qrconnect?appid=...&redirect_uri=...&response_type=code - 回调获取code → POST https://api.weixin.qq.com/sns/oauth2/access_token → 获取openid - POST https://api.weixin.qq.com/sns/userinfo → 获取昵称/头像 4. Google OAuth流程： - 重定向到 Google Authorization URL - 回调获取code → POST https://oauth2.googleapis.com/token → 获取access_token - GET https://www.googleapis.com/oauth2/v2/userinfo → 获取邮箱/昵称/头像 5. 用户关联逻辑： - 查找oauth_accounts表（provider_user_id + provider） - 不存在 → 创建新用户 + 创建oauth_account关联 - 已存在 → 直接登录 6. 生成JWT返回 【运行命令】pytest tests/auth/test_oauth.py -v | M26: 微信和Google OAuth登录实现完成，新用户自动创建，已有用户直接登录
A27: MVP-AUTH-009 | B27: OAuth第三方登录 - 验收 | C27: Acceptance验收 | D27: 用户系统 | E27: P1 | F27: 后端 | G27: 1 | H27: 2026-W14 | I27: 2026-W14 | J27: MVP-AUTH-008 | K27: 未开始 | L27: 【目标】OAuth第三方登录端到端验收 【测试范围】完整OAuth流程（重定向→授权→回调→登录） 【测试场景】 1. 微信OAuth完整流程（使用Mock Provider） 2. Google OAuth完整流程（使用Mock Provider） 3. 新用户自动创建验证 4. 已有用户直接登录验证 5. 用户拒绝授权 → 错误处理 【测试工具】httpx + respx 【验收检查项】 □ 功能正确性：OAuth流程完整，Token返回正确 □ 安全：state参数防CSRF，Token安全 □ 错误处理：授权失败/拒绝/超时 【运行命令】pytest tests/auth/test_oauth.py -v | M27: OAuth验收通过，微信/Google流程正常，安全措施到位
... A138: MVP-INT-006 | B138: 部署 | C138: Acceptance验收 | D138: 集成测试 | E138: P0 | F138: 全栈 | G138: 2 | H138: 2026-W25 | I138: 2026-W25 | J138: MVP-INT-004,MVP-SRV-010 | K138: 未开始 | L138: 【目标】生产环境部署 【实现步骤】 1. K8s apply全部manifest 2. 配置Ingress域名（api.dreamweaver-pen.com） 3. 配置TLS证书（Let's Encrypt） 4. 配置Prometheus监控 5. 配置Grafana面板（API延迟/错误率/资源使用） 6. 配置ELK日志（Elasticsearch+Logstash+Kibana） 7. 验证所有服务健康 【验收检查项】 □ 所有Pod Running □ Ingress可访问 □ TLS证书有效 □ Prometheus数据采集 □ Grafana面板可用 □ ELK日志可查 □ 所有API健康检查通过 【运行命令】kubectl get pods -n dreamweaver && kubectl apply -f k8s/ | M138: 生产环境部署成功，所有服务健康

Sheet v1.5-增强
A1: 任务ID | B1: 任务名称 | C1: TDD阶段 | D1: 所属模块 | E1: 优先级 | F1: 负责角色 | G1: 预估工时 | H1: 开始周 | I1: 结束周 | J1: 前置依赖 | K1: 状态 | L1: 详细任务提示词 | M1: 验收标准 | N1: 备注
A2: V15-COL-001 | B2: 投票模式 - 测试 | C2: Red测试 | D2: 多模型协作 | E2: P1 | F2: AI工程师 | G2: 1 | H2: 2026-W26 | I2: 2026-W26 | K2: 未开始 | L2: 【目标】编写多模型投票模式测试 【测试框架】pytest + pytest-asyncio 【测试文件路径】ai-service/tests/services/collaboration/test_voting.py 【测试用例清单】 1. test_voting_single_task：同一任务发给3个模型 → 返回3个结果 2. test_voting_user_select：用户选择最佳结果 → 记录选择 3. test_voting_statistics：投票统计 → 返回各模型得票数 4. test_voting_timeout：某个模型超时 → 跳过该模型 5. test_voting_all_fail：所有模型失败 → 返回错误 【Mock依赖】Mock多个ModelAdapter 【运行命令】pytest ai-service/tests/services/collaboration/test_voting.py -v | M2: 5个投票模式测试用例通过
A3: V15-COL-002 | B3: 投票模式 - 实现 | C3: Green实现 | D3: 多模型协作 | E3: P1 | F3: AI工程师 | G3: 2 | H3: 2026-W26 | I3: 2026-W26 | J3: V15-COL-001 | K3: 未开始 | L3: 【目标】实现多模型投票模式 【源文件路径】ai-service/app/services/collaboration/voting_mode.py 【实现步骤】 1. 创建VotingMode类 2. 实现execute(task, models, options)： - 并发调用N个模型（asyncio.gather） - 每个模型生成结果 - 收集所有结果 - 返回VotingResult(results, statistics) 3. 用户选择API： - POST /api/v1/ai/vote → 记录用户选择 4. 投票统计： - GET /api/v1/ai/vote/stats → 各模型得票率 5. 超时处理：单个模型超时30秒则跳过 【运行命令】pytest ai-service/tests/services/collaboration/test_voting.py -v | M3: 投票模式实现完成，多模型并发和投票统计正常
A4: V15-COL-003 | B4: 投票模式 - 验收 | C4: Acceptance验收 | D4: 多模型协作 | E4: P1 | F4: AI工程师 | G4: 1 | H4: 2026-W26 | I4: 2026-W26 | J4: V15-COL-002 | K4: 未开始 | L4: 【目标】投票模式端到端验收 【测试场景】 1. 同一任务发给3个模型 → 3个结果展示 2. 用户选择最佳 → 记录成功 3. 投票统计 → 数据正确 【验收检查项】 □ 多模型并发正常 □ 结果展示正确 □ 投票记录正确 □ 超时处理正常 【运行命令】pytest ai-service/tests/services/collaboration/test_voting.py -v | M4: 投票模式验收通过
A5: V15-COL-004 | B5: 接力模式 - 测试 | C5: Red测试 | D5: 多模型协作 | E5: P1 | F5: AI工程师 | G5: 1 | H5: 2026-W26 | I5: 2026-W26 | K5: 未开始 | L5: 【目标】编写接力模式测试 【测试文件路径】ai-service/tests/services/collaboration/test_relay.py 【测试用例清单】 1. test_relay_two_steps：模型A→模型B → 结果传递正确 2. test_relay_multi_steps：多步骤链 → 每步结果缓存 3. test_relay_step_failure：某步失败 → 返回已完成的步骤结果 4. test_relay_custom_chain：自定义步骤链 → 按配置执行 【运行命令】pytest ai-service/tests/services/collaboration/test_relay.py -v | M5: 4个接力模式测试用例通过
A6: V15-COL-005 | B6: 接力模式 - 实现 | C6: Green实现 | D6: 多模型协作 | E6: P1 | F6: AI工程师 | G6: 2 | H6: 2026-W26 | I6: 2026-W26 | J6: V15-COL-004 | K6: 未开始 | L6: 【目标】实现多模型接力模式 【源文件路径】ai-service/app/services/collaboration/relay_mode.py 【实现步骤】 1. 创建RelayMode类 2. 实现execute(task, chain)： - chain: [{model_id, prompt_template, options}, ...] - 按顺序执行每一步 - 上一步的输出作为下一步的输入 - 每步结果缓存到Redis 3. 支持任意步骤链（2-5步） 4. 每步可配置不同的prompt模板和参数 5. 失败处理：某步失败返回已完成步骤的结果 【运行命令】pytest ai-service/tests/services/collaboration/test_relay.py -v | M6: 接力模式实现完成，多步骤链正确执行
A7: V15-COL-006 | B7: 接力模式 - 验收 | C7: Acceptance验收 | D7: 多模型协作 | E7: P1 | F7: AI工程师 | G7: 1 | H7: 2026-W26 | I7: 2026-W26 | J7: V15-COL-005 | K7: 未开始 | L7: 【目标】接力模式端到端验收 【测试场景】 1. 模型A完成→结果传给模型B→模型B继续 2. 多步骤链正确执行 3. 每步结果缓存 【验收检查项】 □ 步骤链执行正确 □ 结果传递正确 □ 缓存生效 □ 失败处理正确 【运行命令】pytest ai-service/tests/services/collaboration/test_relay.py -v | M7: 接力模式验收通过
A8: V15-COL-007 | B8: 辩论模式 - 测试 | C8: Red测试 | D8: 多模型协作 | E8: P1 | F8: AI工程师 | G8: 1 | H8: 2026-W27 | I8: 2026-W27 | K8: 未开始 | L8: 【目标】编写辩论模式测试 【测试文件路径】ai-service/tests/services/collaboration/test_debate.py 【测试用例清单】 1. test_debate_two_models：两个模型提出不同方案 → 返回对比 2. test_debate_display：对比视图展示 → 格式正确 3. test_debate_user_verdict：用户裁决 → 记录选择 4. test_debate_followup：继续追问 → 多轮辩论 【运行命令】pytest ai-service/tests/services/collaboration/test_debate.py -v | M8: 4个辩论模式测试用例通过
A9: V15-COL-008 | B9: 辩论模式 - 实现 | C9: Green实现 | D9: 多模型协作 | E9: P1 | F9: AI工程师 | G9: 2 | H9: 2026-W27 | I9: 2026-W27 | J9: V15-COL-007 | K9: 未开始 | L9: 【目标】实现多模型辩论模式 【源文件路径】ai-service/app/services/collaboration/debate_mode.py 【实现步骤】 1. 创建DebateMode类 2. 实现execute(task, model_a, model_b, rounds=2)： - 模型A提出方案A - 模型B提出方案B - 模型A针对方案B提出反驳 - 模型B针对方案A提出反驳 - 返回DebateResult(proposal_a, proposal_b, rebuttals, summary) 3. 用户裁决API 4. 继续追问：基于用户选择的方向继续深入 【运行命令】pytest ai-service/tests/services/collaboration/test_debate.py -v | M9: 辩论模式实现完成
A10: V15-COL-009 | B10: 辩论模式 - 验收 | C10: Acceptance验收 | D10: 多模型协作 | E10: P1 | F10: AI工程师 | G10: 1 | H10: 2026-W27 | I10: 2026-W27 | J10: V15-COL-008 | K10: 未开始 | L10: 【目标】辩论模式端到端验收 【测试场景】 1. 两个模型提出不同方案 → 对比视图 2. 用户裁决 → 记录 3. 继续追问 → 多轮辩论 【验收检查项】 □ 辩论流程正确 □ 对比视图清晰 □ 裁决记录正确 □ 追问功能正常 【运行命令】pytest ai-service/tests/services/collaboration/test_debate.py -v | M10: 辩论模式验收通过
A11: V15-COL-010 | B11: 融合模式 - 测试 | C11: Red测试 | D11: 多模型协作 | E11: P1 | F11: AI工程师 | G11: 1 | H11: 2026-W27 | I11: 2026-W27 | K11: 未开始 | L11: 【目标】编写融合模式测试 【测试文件路径】ai-service/tests/services/collaboration/test_fusion.py 【测试用例清单】 1. test_fusion_multi_output：多模型输出 → AI融合 2. test_fusion_preserve_strengths：保留各模型优点 3. test_fusion_dedup：去重 4. test_fusion_style_unify：风格统一 【运行命令】pytest ai-service/tests/services/collaboration/test_fusion.py -v | M11: 4个融合模式测试用例通过
A12: V15-COL-011 | B12: 融合模式 - 实现 | C12: Green实现 | D12: 多模型协作 | E12: P1 | F12: AI工程师 | G12: 2 | H12: 2026-W27 | I12: 2026-W27 | J12: V15-COL-010 | K12: 未开始 | L12: 【目标】实现多模型融合模式 【源文件路径】ai-service/app/services/collaboration/fusion_mode.py 【实现步骤】 1. 创建FusionMode类 2. 实现execute(task, models)： - 并发调用多个模型 - 收集所有输出 - 使用AI（Claude/GPT）进行融合： - 分析各输出的优点 - 合并为一个最优结果 - 去重重复内容 - 统一写作风格 - 返回FusionResult(fused_text, source_analysis) 【运行命令】pytest ai-service/tests/services/collaboration/test_fusion.py -v | M12: 融合模式实现完成
A13: V15-COL-012 | B13: 融合模式 - 验收 | C13: Acceptance验收 | D13: 多模型协作 | E13: P1 | F13: AI工程师 | G13: 1 | H13: 2026-W27 | I13: 2026-W27 | J13: V15-COL-011 | K13: 未开始 | L13: 【目标】融合模式端到端验收 【测试场景】 1. 多模型输出 → AI融合 → 保留优点 2. 去重 → 无重复内容 3. 风格统一 → 风格一致 【验收检查项】 □ 融合结果质量高 □ 保留各模型优点 □ 去重正确 □ 风格统一 【运行命令】pytest ai-service/tests/services/collaboration/test_fusion.py -v | M13: 融合模式验收通过
A14: V15-COL-013 | B14: 评审模式 - 测试 | C14: Red测试 | D14: 多模型协作 | E14: P1 | F14: AI工程师 | G14: 1 | H14: 2026-W27 | I14: 2026-W27 | K14: 未开始 | L14: 【目标】编写评审模式测试 【测试文件路径】ai-service/tests/services/collaboration/test_review.py 【测试用例清单】 1. test_review_creation：模型A创作 → 返回文本 2. test_review_evaluation：模型B/C评审 → 返回评分和建议 3. test_review_report：评审报告 → 格式正确 【运行命令】pytest ai-service/tests/services/collaboration/test_review.py -v | M14: 3个评审模式测试用例通过
A15: V15-COL-014 | B15: 评审模式 - 实现 | C15: Green实现 | D15: 多模型协作 | E15: P1 | F15: AI工程师 | G15: 2 | H15: 2026-W27 | I15: 2026-W27 | J15: V15-COL-013 | K15: 未开始 | L15: 【目标】实现多模型评审模式 【源文件路径】ai-service/app/services/collaboration/review_mode.py 【实现步骤】 1. 创建ReviewMode类 2. 实现execute(task, creator_model, reviewer_models)： - creator_model创作文本 - reviewer_models分别评审 - 评审维度：情节合理性/人物一致性/文笔质量/创意性 - 每维度1-10分 - 返回ReviewResult(text, reviews, average_score, suggestions) 3. 评审报告生成 【运行命令】pytest ai-service/tests/services/collaboration/test_review.py -v | M15: 评审模式实现完成
A16: V15-COL-015 | B16: 评审模式 - 验收 | C16: Acceptance验收 | D16: 多模型协作 | E16: P1 | F16: AI工程师 | G16: 1 | H16: 2026-W27 | I16: 2026-W27 | J16: V15-COL-014 | K16: 未开始 | L16: 【目标】评审模式端到端验收 【测试场景】 1. 模型A创作 → 模型B/C评审 → 评分和建议 2. 评审报告展示 【验收检查项】 □ 创作质量合理 □ 评审维度全面 □ 评分合理 □ 建议具体有用 【运行命令】pytest ai-service/tests/services/collaboration/test_review.py -v | M16: 评审模式验收通过
A17: V15-MRG-001 | B17: 段落级Diff - 测试 | C17: Red测试 | D17: 分支合并 | E17: P1 | F17: 后端 | G17: 1 | H17: 2026-W28 | I17: 2026-W28 | J17: MVP-BRN-009 | K17: 未开始 | L17: 【目标】编写段落级Diff算法测试 【测试框架】pytest 【测试文件路径】server/service/branch-service/tests/test_diff.py 【测试用例清单】 1. test_three_way_merge：三方合并算法 → 正确合并 2. test_find_common_ancestor：找到共同祖先 → 正确 3. test_detect_conflicts：标记冲突区域 → 正确 4. test_no_conflict_merge：无冲突合并 → 直接合并 5. test_complex_conflict：复杂冲突 → 正确标记 【运行命令】pytest server/service/branch-service/tests/test_diff.py -v | M17: 5个Diff测试用例通过
A18: V15-MRG-002 | B18: 段落级Diff - 实现 | C18: Green实现 | D18: 分支合并 | E18: P1 | F18: 后端 | G18: 3 | H18: 2026-W28 | I18: 2026-W28 | J18: V15-MRG-001 | K18: 未开始 | L18: 【目标】实现段落级三方合并算法 【源文件路径】server/service/branch-service/internal/diff/ 【实现步骤】 1. 实现三方合并（Three-way Merge）： - 输入：base_text, branch_a_text, branch_b_text - 按段落切分（双换行符分隔） - 使用LCS（最长公共子序列）算法比较差异 - 找到共同祖先版本 - 对比分叉点后的差异 - 标记冲突区域 2. 冲突标记格式： <<<<<<< BRANCH_A 分支A的内容 ======= 分支B的内容 >>>>>>> BRANCH_B 3. 自动合并无冲突的部分 【运行命令】pytest server/service/branch-service/tests/test_diff.py -v | M18: 段落级Diff算法实现完成，三方合并正确
A19: V15-MRG-003 | B19: 段落级Diff - 验收 | C19: Acceptance验收 | D19: 分支合并 | E19: P1 | F19: 后端 | G19: 1 | H19: 2026-W28 | I19: 2026-W28 | J19: V15-MRG-002 | K19: 未开始 | L19: 【目标】段落级Diff验收 【测试场景】 1. 无冲突合并 → 直接合并成功 2. 有冲突合并 → 正确标记冲突区域 3. 复杂冲突 → 多处冲突正确标记 【验收检查项】 □ 三方合并正确 □ 冲突标记准确 □ 无冲突部分自动合并 【运行命令】pytest server/service/branch-service/tests/test_diff.py -v | M19: 段落级Diff验收通过
A20: V15-MRG-004 | B20: AI辅助合并 - 测试 | C20: Red测试 | D20: 分支合并 | E20: P1 | F20: AI工程师 | G20: 1 | H20: 2026-W28 | I20: 2026-W28 | J20: V15-MRG-002 | K20: 未开始 | L20: 【目标】编写AI辅助合并测试 【测试文件路径】ai-service/tests/services/test_merge_assistant.py 【测试用例清单】 1. test_analyze_diff：AI分析两个分支差异 → 返回分析 2. test_suggest_merge：建议最优合并方案 → 返回建议 3. test_resolve_conflict：冲突自动解决建议 → 返回解决建议 4. test_merge_preview：合并预览 → 返回预览文本 【运行命令】pytest ai-service/tests/services/test_merge_assistant.py -v | M20: 4个AI辅助合并测试用例通过
A21: V15-MRG-005 | B21: AI辅助合并 - 实现 | C21: Green实现 | D21: 分支合并 | E21: P1 | F21: AI工程师 | G21: 2 | H21: 2026-W28 | I21: 2026-W28 | J21: V15-MRG-004 | K21: 未开始 | L21: 【目标】实现AI辅助合并服务 【源文件路径】ai-service/app/services/merge_assistant.py 【实现步骤】 1. 创建MergeAssistant类 2. 实现analyze_diff(branch_a_content, branch_b_content)： - 使用AI分析两分支差异 - 识别关键差异点 - 评估每个差异的影响 3. 实现suggest_merge(diff_result)： - AI建议最优合并方案 - 对每个冲突区域给出建议 4. 实现resolve_conflict(conflict)： - AI自动解决冲突 - 保留两分支优点 【运行命令】pytest ai-service/tests/services/test_merge_assistant.py -v | M21: AI辅助合并实现完成
A22: V15-MRG-006 | B22: AI辅助合并 - 验收 | C22: Acceptance验收 | D22: 分支合并 | E22: P1 | F22: AI工程师 | G22: 1 | H22: 2026-W28 | I22: 2026-W28 | J22: V15-MRG-005 | K22: 未开始 | L22: 【目标】AI辅助合并验收 【测试场景】 1. AI分析差异 → 分析准确 2. 建议合并方案 → 方案合理 3. 冲突自动解决 → 解决质量高 【验收检查项】 □ 差异分析准确 □ 合并建议合理 □ 冲突解决质量高 【运行命令】pytest ai-service/tests/services/test_merge_assistant.py -v | M22: AI辅助合并验收通过
A23: V15-MRG-007 | B23: 合并UI - 测试 | C23: Red测试 | D23: 分支合并 | E23: P1 | F23: 前端 | G23: 1 | H23: 2026-W29 | I23: 2026-W29 | J23: V15-MRG-003 | K23: 未开始 | L23: 【目标】编写合并UI测试 【测试文件路径】extensions/dw-branch-manager/__tests__/MergeView.test.ts 【测试用例清单】 1. test_side_by_side_view：并排对比视图渲染 2. test_conflict_highlight：冲突高亮 3. test_conflict_resolution：逐个冲突选择 4. test_merge_preview：合并预览 5. test_undo_support：撤销支持 【运行命令】npx vitest run extensions/dw-branch-manager/__tests__/MergeView.test.ts | M23: 5个合并UI测试用例通过
A24: V15-MRG-008 | B24: 合并UI - 实现 | C24: Green实现 | D24: 分支合并 | E24: P1 | F24: 前端 | G24: 3 | H24: 2026-W29 | I24: 2026-W29 | J24: V15-MRG-007 | K24: 未开始 | L24: 【目标】实现分支合并UI 【源文件路径】extensions/dw-branch-manager/src/webview/MergeView.ts 【实现步骤】 1. 并排对比视图： - 左侧：分支A内容 - 右侧：分支B内容 - 中间：合并结果 2. 冲突高亮： - 冲突区域红色/蓝色高亮 - 非冲突部分绿色高亮（已自动合并） 3. 逐个冲突选择： - 上一个/下一个冲突导航 - 选择A/选择B/保留两者 4. 合并预览： - 实时显示合并结果 - AI建议按钮 5. 撤销支持： - 每次选择可撤销 - Ctrl+Z撤销 【运行命令】npx vitest run extensions/dw-branch-manager/__tests__/MergeView.test.ts | M24: 合并UI实现完成
A25: V15-MRG-009 | B25: 合并UI - 验收 | C25: Acceptance验收 | D25: 分支合并 | E25: P1 | F25: 前端 | G25: 1 | H25: 2026-W29 | I25: 2026-W29 | J25: V15-MRG-008 | K25: 未开始 | L25: 【目标】合并UI端到端验收 【测试场景】 1. 并排对比视图 → 显示正确 2. 冲突高亮 → 颜色正确 3. 逐个冲突选择 → 导航和选择正常 4. 合并预览 → 实时更新 5. 撤销 → Ctrl+Z正常 【验收检查项】 □ 并排对比正确 □ 冲突高亮清晰 □ 选择操作正常 □ 预览实时更新 □ 撤销可用 【运行命令】F5启动Extension Development Host | M25: 合并UI验收通过
A26: V15-DAI-001 | B26: AI文本检测 - 测试 | C26: Red测试 | D26: 去AI味引擎 | E26: P1 | F26: AI工程师 | G26: 1 | H26: 2026-W30 | I26: 2026-W30 | K26: 未开始 | L26: 【目标】编写AI文本检测测试 【测试文件路径】ai-service/tests/services/test_ai_detector.py 【测试用例清单】 1. test_detect_ai_text：检测AI生成文本 → 评分>70 2. test_detect_human_text：检测人类写作 → 评分<30 3. test_detect_common_patterns：识别常见AI句式 → 列出 4. test_detect_overly_neat：识别过度工整结构 → 标记 5. test_score_range：评分范围0-100 → 正确 【运行命令】pytest ai-service/tests/services/test_ai_detector.py -v | M26: 5个AI检测测试用例通过
A27: V15-DAI-002 | B27: AI文本检测 - 实现 | C27: Green实现 | D27: 去AI味引擎 | E27: P1 | F27: AI工程师 | G27: 2 | H27: 2026-W30 | I27: 2026-W30 | J27: V15-DAI-001 | K27: 未开始 | L27: 【目标】实现AI文本检测服务 【源文件路径】ai-service/app/services/ai_detector.py 【实现步骤】 1. 创建AIDetector类 2. 实现detect(text) → AIDetectionResult(score, patterns, suggestions) 3. 检测维度： - 常见AI句式（"值得注意的是"、"总而言之"等） - 过度工整的段落结构 - 缺乏个人风格的用词 - 重复的句式模式 4. 评分算法：综合各维度给出0-100分 5. 返回具体AI味标记位置和建议 【运行命令】pytest ai-service/tests/services/test_ai_detector.py -v | M27: AI文本检测实现完成
A28: V15-DAI-003 | B28: AI文本检测 - 验收 | C28: Acceptance验收 | D28: 去AI味引擎 | E28: P1 | F28: AI工程师 | G28: 1 | H28: 2026-W30 | I28: 2026-W30 | J28: V15-DAI-002 | K28: 未开始 | L28: 【目标】AI文本检测验收 【测试场景】 1. AI生成文本 → 评分>70 2. 人类写作 → 评分<30 3. 混合文本 → 评分合理 【验收检查项】 □ 检测准确率≥85% □ 评分合理 □ 标记位置准确 【运行命令】pytest ai-service/tests/services/test_ai_detector.py -v | M28: AI文本检测验收通过
A29: V15-DAI-004 | B29: 智能去AI味 - 测试 | C29: Red测试 | D29: 去AI味引擎 | E29: P1 | F29: AI工程师 | G29: 1 | H29: 2026-W30 | I29: 2026-W30 | J29: V15-DAI-003 | K29: 未开始 | L29: 【目标】编写智能去AI味测试 【测试文件路径】ai-service/tests/services/test_de_ai.py 【测试用例清单】 1. test_multi_model_rewrite：多模型交叉改写 → 降低检测率 2. test_polish_pipeline：改写→润色→人性化 → 流水线正确 3. test_detection_score_decrease：处理后检测评分降低 【运行命令】pytest ai-service/tests/services/test_de_ai.py -v | M29: 3个去AI味测试用例通过
A30: V15-DAI-005 | B30: 智能去AI味 - 实现 | C30: Green实现 | D30: 去AI味引擎 | E30: P1 | F30: AI工程师 | G30: 3 | H30: 2026-W30 | I30: 2026-W30 | J30: V15-DAI-004 | K30: 未开始 | L30: 【目标】实现智能去AI味服务 【源文件路径】ai-service/app/services/de_ai_service.py 【实现步骤】 1. 创建DeAIService类 2. 实现三阶段流水线： - 阶段1：模型A改写（打破AI句式） - 阶段2：模型B润色（提升文笔） - 阶段3：模型C人性化（注入个人风格） 3. 每阶段使用不同模型（避免单一模型偏见） 4. 处理后重新检测，验证评分降低 5. 如果评分仍>50，可再次处理 【运行命令】pytest ai-service/tests/services/test_de_ai.py -v | M30: 智能去AI味实现完成
A31: V15-DAI-006 | B31: 智能去AI味 - 验收 | C31: Acceptance验收 | D31: 去AI味引擎 | E31: P1 | F31: AI工程师 | G31: 1 | H31: 2026-W30 | I31: 2026-W30 | J31: V15-DAI-005 | K31: 未开始 | L31: 【目标】智能去AI味验收 【测试场景】 1. AI文本 → 去AI味处理 → 检测评分降低 2. 处理后文本质量 → 可读性不下降 3. 多次处理 → 评分持续降低 【验收检查项】 □ 检测评分降低≥30% □ 文本质量不下降 □ 处理时间合理（<30s/千字） 【运行命令】pytest ai-service/tests/services/test_de_ai.py -v | M31: 智能去AI味验收通过
A32: V15-DAI-007 | B32: 个性化风格学习 - 测试 | C32: Red测试 | D32: 去AI味引擎 | E32: P2 | F32: AI工程师 | G32: 1 | H32: 2026-W31 | I32: 2026-W31 | J32: V15-DAI-005 | K32: 未开始 | L32: 【目标】编写个性化风格学习测试 【测试文件路径】ai-service/tests/services/test_style_learner.py 【测试用例清单】 1. test_collect_style_features：收集写作风格特征 2. test_build_style_profile：构建风格Profile 3. test_inject_style：AI生成时注入风格 【运行命令】pytest ai-service/tests/services/test_style_learner.py -v | M32: 3个风格学习测试用例通过
A33: V15-DAI-008 | B33: 个性化风格学习 - 实现 | C33: Green实现 | D33: 去AI味引擎 | E33: P2 | F33: AI工程师 | G33: 3 | H33: 2026-W31 | I33: 2026-W31 | J33: V15-DAI-007 | K33: 未开始 | L33: 【目标】实现个性化风格学习 【源文件路径】ai-service/app/services/style_learner.py 【实现步骤】 1. 创建StyleLearner类 2. 收集用户历史文本 → 分析风格特征： - 常用词汇和表达 - 句式偏好（长短句比例） - 描写风格（细腻/简洁/华丽） - 对话风格 3. 构建风格Profile → 存储到数据库 4. AI生成时注入风格 → 修改system prompt 【运行命令】pytest ai-service/tests/services/test_style_learner.py -v | M33: 个性化风格学习实现完成
A34: V15-DAI-009 | B34: 个性化风格学习 - 验收 | C34: Acceptance验收 | D34: 去AI味引擎 | E34: P2 | F34: AI工程师 | G34: 1 | H34: 2026-W31 | I34: 2026-W31 | J34: V15-DAI-008 | K34: 未开始 | L34: 【目标】个性化风格学习验收 【测试场景】 1. 收集历史文本 → 风格特征提取 2. 构建Profile → 存储正确 3. 注入风格 → AI生成文本风格匹配 【验收检查项】 □ 风格特征提取合理 □ Profile存储正确 □ 风格注入有效 【运行命令】pytest ai-service/tests/services/test_style_learner.py -v | M34: 个性化风格学习验收通过
A35: V15-MDL-001 | B35: Gemini适配器 - 测试 | C35: Red测试 | D35: 模型扩展 | E35: P1 | F35: AI工程师 | G35: 1 | H35: 2026-W32 | I35: 2026-W32 | K35: 未开始 | L35: 【目标】编写Gemini适配器测试 【测试文件路径】ai-service/tests/adapters/test_gemini.py 【测试用例清单】 1. test_generate_success：Mock Gemini API → 返回正确 2. test_stream_success：SSE流正确 3. test_error_handling：错误处理 【运行命令】pytest ai-service/tests/adapters/test_gemini.py -v | M35: 3个Gemini测试用例通过
A36: V15-MDL-002 | B36: Gemini适配器 - 实现 | C36: Green实现 | D36: 模型扩展 | E36: P1 | F36: AI工程师 | G36: 2 | H36: 2026-W32 | I36: 2026-W32 | J36: V15-MDL-001 | K36: 未开始 | L36: 【目标】实现Gemini适配器 【源文件路径】ai-service/app/adapters/gemini_adapter.py 【实现步骤】 1. 继承BaseModelAdapter 2. 使用Google Generative AI SDK（google-generativeai） 3. 模型：gemini-2.0-flash / gemini-2.0-pro 4. 实现generate/stream/count_tokens/health_check 5. 注册到ModelAdapterFactory 【运行命令】pytest ai-service/tests/adapters/test_gemini.py -v | M36: Gemini适配器实现完成
A37: V15-MDL-003 | B37: Gemini适配器 - 验收 | C37: Acceptance验收 | D37: 模型扩展 | E37: P1 | F37: AI工程师 | G37: 1 | H37: 2026-W32 | I37: 2026-W32 | J37: V15-MDL-002 | K37: 未开始 | L37: 【目标】Gemini适配器验收 【验收检查项】 □ API调用正常 □ 流式响应正确 □ 错误处理完善 【运行命令】pytest ai-service/tests/adapters/test_gemini.py -v -m integration | M37: Gemini适配器验收通过
A38: V15-MDL-004 | B38: Llama适配器 - 测试 | C38: Red测试 | D38: 模型扩展 | E38: P2 | F38: AI工程师 | G38: 1 | H38: 2026-W32 | I38: 2026-W32 | K38: 未开始 | L38: 【目标】编写Llama适配器测试（本地部署） 【测试文件路径】ai-service/tests/adapters/test_llama.py 【测试用例清单】 1. test_generate_success：Mock Llama API（OpenAI兼容） 2. test_stream_success：SSE流 3. test_local_deployment：本地部署连接 【运行命令】pytest ai-service/tests/adapters/test_llama.py -v | M38: 3个Llama测试用例通过
A39: V15-MDL-005 | B39: Llama适配器 - 实现 | C39: Green实现 | D39: 模型扩展 | E39: P2 | F39: AI工程师 | G39: 2 | H39: 2026-W32 | I39: 2026-W32 | J39: V15-MDL-004 | K39: 未开始 | L39: 【目标】实现Llama适配器（支持本地部署） 【源文件路径】ai-service/app/adapters/llama_adapter.py 【实现步骤】 1. 使用OpenAI兼容API格式（vLLM/Ollama） 2. base_url可配置（本地或远程） 3. 模型：llama-3-70b / llama-3-8b 4. 实现generate/stream/count_tokens/health_check 5. 注册到ModelAdapterFactory 【运行命令】pytest ai-service/tests/adapters/test_llama.py -v | M39: Llama适配器实现完成
A40: V15-MDL-006 | B40: Llama适配器 - 验收 | C40: Acceptance验收 | D40: 模型扩展 | E40: P2 | F40: AI工程师 | G40: 1 | H40: 2026-W32 | I40: 2026-W32 | J40: V15-MDL-005 | K40: 未开始 | L40: 【目标】Llama适配器验收 【验收检查项】 □ 本地部署连接正常 □ API调用正常 □ 流式响应正确 【运行命令】pytest ai-service/tests/adapters/test_llama.py -v | M40: Llama适配器验收通过
...

Sheet v2.0-生态
A1: 任务ID | B1: 任务名称 | C1: TDD阶段 | D1: 所属模块 | E1: 优先级 | F1: 负责角色 | G1: 预估工时 | H1: 开始周 | I1: 结束周 | J1: 前置依赖 | K1: 状态 | L1: 详细任务提示词 | M1: 验收标准 | N1: 备注
A2: V20-TPL-001 | B2: 模板CRUD API - 测试 | C2: Red测试 | D2: 模板市场 | E2: P2 | F2: 后端 | G2: 1 | H2: 2026-W36 | I2: 2026-W36 | K2: 未开始 | L2: 【目标】编写模板CRUD API测试 【测试框架】pytest + httpx 【测试文件路径】server/service/template-service/tests/test_template_api.py 【测试用例清单】 1. test_create_template：创建模板 → 201 2. test_get_template：获取模板 → 200 3. test_update_template：更新模板 → 200 4. test_delete_template：删除模板 → 204 5. test_list_templates：模板列表 → 200 + 分页 6. test_template_categories：分类筛选 → 正确过滤 【运行命令】pytest server/service/template-service/tests/test_template_api.py -v | M2: 6个模板API测试用例通过
A3: V20-TPL-002 | B3: 模板CRUD API - 实现 | C3: Green实现 | D3: 模板市场 | E3: P2 | F3: 后端 | G3: 2 | H3: 2026-W36 | I3: 2026-W36 | J3: V20-TPL-001 | K3: 未开始 | L3: 【目标】实现模板CRUD API 【源文件路径】server/service/template-service/ 【API端点】 - POST /templates → 创建模板 - GET /templates → 列表（分页+分类筛选+排序） - GET /templates/:id → 获取详情 - PUT /templates/:id → 更新 - DELETE /templates/:id → 删除 - POST /templates/:id/clone → 克隆模板 【数据模型】 - templates: { id, author_id, name, description, category, genre, structure_json, settings_json, is_public, download_count, rating, created_at, updated_at } 【实现步骤】 1. CRUD操作 2. 分类筛选（玄幻/都市/科幻/言情/历史/悬疑/其他） 3. 排序（热门/最新/评分） 4. 克隆功能 【运行命令】pytest server/service/template-service/tests/test_template_api.py -v | M3: 模板CRUD API实现完成
A4: V20-TPL-003 | B4: 模板CRUD API - 验收 | C4: Acceptance验收 | D4: 模板市场 | E4: P2 | F4: 后端 | G4: 1 | H4: 2026-W36 | I4: 2026-W36 | J4: V20-TPL-002 | K4: 未开始 | L4: 【目标】模板CRUD API验收 【验收检查项】 □ CRUD完整 □ 分类筛选正确 □ 排序正确 □ 克隆功能正常 【运行命令】pytest server/service/template-service/tests/test_template_api.py -v | M4: 模板CRUD API验收通过
A5: V20-TPL-004 | B5: 模板浏览搜索 - 测试 | C5: Red测试 | D5: 模板市场 | E5: P2 | F5: 后端 | G5: 1 | H5: 2026-W36 | I5: 2026-W36 | J5: V20-TPL-002 | K5: 未开始 | L5: 【目标】编写模板搜索测试 【测试文件路径】server/service/template-service/tests/test_template_search.py 【测试用例清单】 1. test_fulltext_search：全文搜索 → 返回匹配 2. test_tag_search：标签搜索 → 正确过滤 3. test_genre_filter：类型筛选 → 正确 4. test_sort_by_rating：按评分排序 → 正确 【运行命令】pytest server/service/template-service/tests/test_template_search.py -v | M5: 4个模板搜索测试用例通过
A6: V20-TPL-005 | B6: 模板浏览搜索 - 实现 | C6: Green实现 | D6: 模板市场 | E6: P2 | F6: 后端 | G6: 2 | H6: 2026-W36 | I6: 2026-W36 | J6: V20-TPL-004 | K6: 未开始 | L6: 【目标】实现模板搜索功能 【源文件路径】server/service/template-service/internal/search.go 【实现步骤】 1. Elasticsearch全文搜索（名称+描述+标签） 2. 标签搜索 3. 类型筛选 4. 多维排序（热门/最新/评分/下载量） 5. 搜索建议（自动补全） 【运行命令】pytest server/service/template-service/tests/test_template_search.py -v | M6: 模板搜索实现完成
A7: V20-TPL-006 | B7: 模板浏览搜索 - 验收 | C7: Acceptance验收 | D7: 模板市场 | E7: P2 | F7: 后端 | G7: 1 | H7: 2026-W36 | I7: 2026-W36 | J7: V20-TPL-005 | K7: 未开始 | L7: 【目标】模板搜索验收 【验收检查项】 □ 全文搜索准确 □ 标签搜索正确 □ 排序正确 □ 搜索建议可用 【运行命令】pytest server/service/template-service/tests/test_template_search.py -v | M7: 模板搜索验收通过
A8: V20-TPL-007 | B8: 模板创建向导 - 测试 | C8: Red测试 | D8: 模板市场 | E8: P2 | F8: 前端 | G8: 1 | H8: 2026-W37 | I8: 2026-W37 | J8: V20-TPL-002 | K8: 未开始 | L8: 【目标】编写模板创建向导测试 【测试文件路径】extensions/dw-template-market/__tests__/TemplateWizard.test.ts 【测试用例清单】 1. test_wizard_steps：向导步骤正确 2. test_template_structure_editor：结构编辑器 3. test_preview：模板预览 【运行命令】npx vitest run extensions/dw-template-market/__tests__/TemplateWizard.test.ts | M8: 3个向导测试用例通过
A9: V20-TPL-008 | B9: 模板创建向导 - 实现 | C9: Green实现 | D9: 模板市场 | E9: P2 | F9: 前端 | G9: 3 | H9: 2026-W37 | I9: 2026-W37 | J9: V20-TPL-007 | K9: 未开始 | L9: 【目标】实现模板创建向导 【源文件路径】extensions/dw-template-market/src/webview/TemplateWizard.ts 【实现步骤】 1. 多步骤向导： - 步骤1：基本信息（名称/描述/分类/标签） - 步骤2：结构定义（卷/章/节大纲） - 步骤3：角色设定模板 - 步骤4：世界观设定模板 - 步骤5：AI配置（推荐模型/写作风格） 2. 可视化结构编辑器（拖拽排序） 3. 实时预览 4. 保存和发布 【运行命令】npx vitest run extensions/dw-template-market/__tests__/TemplateWizard.test.ts | M9: 模板创建向导实现完成
A10: V20-TPL-009 | B10: 模板创建向导 - 验收 | C10: Acceptance验收 | D10: 模板市场 | E10: P2 | F10: 前端 | G10: 1 | H10: 2026-W37 | I10: 2026-W37 | J10: V20-TPL-008 | K10: 未开始 | L10: 【目标】模板创建向导验收 【验收检查项】 □ 向导步骤流畅 □ 结构编辑器可用 □ 预览正确 □ 保存发布正常 【运行命令】F5启动Extension Development Host | M10: 模板创建向导验收通过
A11: V20-TPL-010 | B11: 模板版本管理 - 测试 | C11: Red测试 | D11: 模板市场 | E11: P2 | F11: 后端 | G11: 1 | H11: 2026-W37 | I11: 2026-W37 | J11: V20-TPL-002 | K11: 未开始 | L11: 【目标】编写模板版本管理测试 【测试文件路径】server/service/template-service/tests/test_template_version.py 【测试用例清单】 1. test_create_version：创建版本 → 201 2. test_list_versions：版本列表 → 正确 3. test_rollback：版本回滚 → 正确 【运行命令】pytest server/service/template-service/tests/test_template_version.py -v | M11: 3个版本管理测试用例通过
A12: V20-TPL-011 | B12: 模板版本管理 - 实现 | C12: Green实现 | D12: 模板市场 | E12: P2 | F12: 后端 | G12: 2 | H12: 2026-W37 | I12: 2026-W37 | J12: V20-TPL-010 | K12: 未开始 | L12: 【目标】实现模板版本管理 【源文件路径】server/service/template-service/internal/version.go 【实现步骤】 1. 版本快照：每次更新自动创建版本 2. 版本列表：GET /templates/:id/versions 3. 版本对比：GET /templates/:id/diff/:v1/:v2 4. 版本回滚：POST /templates/:id/rollback/:version 5. 更新日志 【运行命令】pytest server/service/template-service/tests/test_template_version.py -v | M12: 模板版本管理实现完成
A13: V20-TPL-012 | B13: 模板版本管理 - 验收 | C13: Acceptance验收 | D13: 模板市场 | E13: P2 | F13: 后端 | G13: 1 | H13: 2026-W37 | I13: 2026-W37 | J13: V20-TPL-011 | K13: 未开始 | L13: 【目标】模板版本管理验收 【验收检查项】 □ 版本快照正常 □ 版本对比正确 □ 回滚功能正常 【运行命令】pytest server/service/template-service/tests/test_template_version.py -v | M13: 模板版本管理验收通过
A14: V20-ANA-001 | B14: 数据采集服务 - 测试 | C14: Red测试 | D14: 数据统计 | E14: P2 | F14: 后端 | G14: 1 | H14: 2026-W38 | I14: 2026-W38 | K14: 未开始 | L14: 【目标】编写数据采集服务测试 【测试文件路径】server/service/analytics-service/tests/test_collector.py 【测试用例清单】 1. test_collect_word_count：采集字数数据 2. test_collect_ai_usage：采集AI使用数据 3. test_collect_session：采集写作会话数据 4. test_collect_interval：定时采集 【运行命令】pytest server/service/analytics-service/tests/test_collector.py -v | M14: 4个数据采集测试用例通过
A15: V20-ANA-002 | B15: 数据采集服务 - 实现 | C15: Green实现 | D15: 数据统计 | E15: P2 | F15: 后端 | G15: 2 | H15: 2026-W38 | I15: 2026-W38 | J15: V20-ANA-001 | K15: 未开始 | L15: 【目标】实现数据采集服务 【源文件路径】server/service/analytics-service/internal/collector.go 【实现步骤】 1. 采集维度： - 字数统计（日/周/月） - AI使用次数和Token消耗 - 写作会话时长 - 章节完成数 - 模型使用分布 2. 定时采集（每小时） 3. 数据聚合（日/周/月汇总） 4. 存储到PostgreSQL analytics表 【运行命令】pytest server/service/analytics-service/tests/test_collector.py -v | M15: 数据采集服务实现完成
A16: V20-ANA-003 | B16: 数据采集服务 - 验收 | C16: Acceptance验收 | D16: 数据统计 | E16: P2 | F16: 后端 | G16: 1 | H16: 2026-W38 | I16: 2026-W38 | J16: V20-ANA-002 | K16: 未开始 | L16: 【目标】数据采集服务验收 【验收检查项】 □ 采集数据准确 □ 定时采集正常 □ 数据聚合正确 【运行命令】pytest server/service/analytics-service/tests/test_collector.py -v | M16: 数据采集服务验收通过
A17: V20-ANA-004 | B17: 统计分析API - 测试 | C17: Red测试 | D17: 数据统计 | E17: P2 | F17: 后端 | G17: 1 | H17: 2026-W38 | I17: 2026-W38 | J17: V20-ANA-002 | K17: 未开始 | L17: 【目标】编写统计分析API测试 【测试文件路径】server/service/analytics-service/tests/test_stats_api.py 【测试用例清单】 1. test_get_daily_stats：日统计 → 正确 2. test_get_weekly_stats：周统计 → 正确 3. test_get_model_usage：模型使用分布 → 正确 4. test_get_writing_trends：写作趋势 → 正确 【运行命令】pytest server/service/analytics-service/tests/test_stats_api.py -v | M17: 4个统计分析测试用例通过
A18: V20-ANA-005 | B18: 统计分析API - 实现 | C18: Green实现 | D18: 数据统计 | E18: P2 | F18: 后端 | G18: 2 | H18: 2026-W38 | I18: 2026-W38 | J18: V20-ANA-004 | K18: 未开始 | L18: 【目标】实现统计分析API 【源文件路径】server/service/analytics-service/ 【API端点】 - GET /analytics/daily → 日统计 - GET /analytics/weekly → 周统计 - GET /analytics/monthly → 月统计 - GET /analytics/model-usage → 模型使用分布 - GET /analytics/writing-trends → 写作趋势 - GET /analytics/goals → 目标完成度 【实现步骤】 1. SQL聚合查询 2. 时间范围筛选 3. 数据可视化格式 【运行命令】pytest server/service/analytics-service/tests/test_stats_api.py -v | M18: 统计分析API实现完成
A19: V20-ANA-006 | B19: 统计分析API - 验收 | C19: Acceptance验收 | D19: 数据统计 | E19: P2 | F19: 后端 | G19: 1 | H19: 2026-W38 | I19: 2026-W38 | J19: V20-ANA-005 | K19: 未开始 | L19: 【目标】统计分析API验收 【验收检查项】 □ 日/周/月统计正确 □ 模型使用分布正确 □ 写作趋势数据正确 【运行命令】pytest server/service/analytics-service/tests/test_stats_api.py -v | M19: 统计分析API验收通过
A20: V20-ANA-007 | B20: 可视化面板Webview - 测试 | C20: Red测试 | D20: 数据统计 | E20: P2 | F20: 前端 | G20: 1 | H20: 2026-W39 | I20: 2026-W39 | J20: V20-ANA-005 | K20: 未开始 | L20: 【目标】编写可视化面板测试 【测试文件路径】extensions/dw-analytics/__tests__/AnalyticsPanel.test.ts 【测试用例清单】 1. test_render_charts：图表渲染正确 2. test_date_range_selector：日期范围选择 3. test_export_report：导出报告 【运行命令】npx vitest run extensions/dw-analytics/__tests__/AnalyticsPanel.test.ts | M20: 3个可视化面板测试用例通过
